Workbook

Sheet 變數
A1: blocky名稱 | B1: 變數
A2: imi_esp32car_init | B2: value_rx
B3: value_tx
B4: value_ssid
B5: value_wifiPwd
B6: value_lineToken
B7: value_mqttUser
B8: value_mqttPwd
B9: value_mqttPort
B10: dropdown_mqttTopic
B11: dropdown_uartTopic

Sheet DEFINITION
A1: DEFINITION區 1次 | C1: 完整程式碼： | D1: ="Blockly.Arduino.definitions_['"&D2&"'] = '"&D3&"';" -> Blockly.Arduino.definitions_['imi_esp32car_init'] = '#include <SoftwareSerial.h>\n#include <WiFi.h>\n#include <PubSubClient.h>\n#include <WiFiClientSecure.h>\n//與Mega通訊\nconst char* MAP_SET = "mapSet";\nconst char* GOODS_LOAD = "goodsLoad";\nconst char* LINE_NOTIFY = "lineNotify";\nconst char* CAR_GPS = "carGps";\n//UART通訊\n''SoftwareSerial MegaSerial('+value_rx+',' +value_tx+');'\n//WiFi設定\n''const char* ssid ="' +value_ssid+'";'\n''const char* password ="' +value_wifiPwd+'";'\n//LINE權杖\n''String lineToken ="' +value_lineToken+'";'\n//---- HiveMQ設定 Start -----\nconst char* mqtt_server = "xxxxxxxx.s2.eu.hivemq.cloud";\n''const char* mqtt_username ="' +value_mqttUser+'";'\n''const char* mqtt_password ="' +value_mqttPwd+'";'\n''const int mqtt_port =' +value_mqttPort+';'\n//Topic主題\nconst char* TOPIC_MAP_SET = "imiRobot/map/set";\nconst char* TOPIC_CAR_STANDBY = "imiRobot/car/standby";\nconst char* TOPIC_CAR_GPS = "imiRobot/car/gps";\nconst char* TOPIC_GOODS_LOAD = "imiRobot/goods/load";\nconst char* TOPIC_CAR_LOWPOWER = "imiRobot/car/lowPower";\n//發佈者 傳送的消息內容\nchar* mqttSendMsg = "";\n//訂閱者 接收的消息內容\nString mqttGetMsg = "";\nWiFiClientSecure espClient;\nPubSubClient client(espClient);\n// HiveMQ Cloud Let's Encrypt CA certificate\nstatic const char* root_ca PROGMEM = R"EOF(\n-----BEGIN CERTIFICATE-----\nMIIFazCCA1OgAwIBAgIRAIIQz7DSQONZRGPgu2OCiwAwDQYJKoZIhvcNAQELBQAw\nTzELMAkGA1UEBhMCVVMxKTAnBgNVBAoTIEludGVybmV0IFNlY3VyaXR5IFJlc2Vh\ncmNoIEdyb3VwMRUwEwYDVQQDEwxJU1JHIFJvb3QgWDEwHhcNMTUwNjA0MTEwNDM4\nWhcNMzUwNjA0MTEwNDM4WjBPMQswCQYDVQQGEwJVUzEpMCcGA1UEChMgSW50ZXJu\nZXQgU2VjdXJpdHkgUmVzZWFyY2ggR3JvdXAxFTATBgNVBAMTDElTUkcgUm9vdCBY\nMTCCAiIwDQYJKoZIhvcNAQEBBQADggIPADCCAgoCggIBAK3oJHP0FDfzm54rVygc\nh77ct984kIxuPOZXoHj3dcKi/vVqbvYATyjb3miGbESTtrFj/RQSa78f0uoxmyF+\n0TM8ukj13Xnfs7j/EvEhmkvBioZxaUpmZmyPfjxwv60pIgbz5MDmgK7iS4+3mX6U\nA5/TR5d8mUgjU+g4rk8Kb4Mu0UlXjIB0ttov0DiNewNwIRt18jA8+o+u3dpjq+sW\nT8KOEUt+zwvo/7V3LvSye0rgTBIlDHCNAymg4VMk7BPZ7hm/ELNKjD+Jo2FR3qyH\nB5T0Y3HsLuJvW5iB4YlcNHlsdu87kGJ55tukmi8mxdAQ4Q7e2RCOFvu396j3x+UC\nB5iPNgiV5+I3lg02dZ77DnKxHZu8A/lJBdiB3QW0KtZB6awBdpUKD9jf1b0SHzUv\nKBds0pjBqAlkd25HN7rOrFleaJ1/ctaJxQZBKT5ZPt0m9STJEadao0xAH0ahmbWn\nOlFuhjuefXKnEgV4We0+UXgVCwOPjdAvBbI+e0ocS3MFEvzG6uBQE3xDk3SzynTn\njh8BCNAw1FtxNrQHusEwMFxIt4I7mKZ9YIqioymCzLq9gwQbooMDQaHWBfEbwrbw\nqHyGO0aoSCqI3Haadr8faqU9GY/rOPNk3sgrDQoo//fb4hVC1CLQJ13hef4Y53CI\nrU7m2Ys6xt0nUW7/vGT1M0NPAgMBAAGjQjBAMA4GA1UdDwEB/wQEAwIBBjAPBgNV\nHRMBAf8EBTADAQH/MB0GA1UdDgQWBBR5tFnme7bl5AFzgAiIyBpY9umbbjANBgkq\nhkiG9w0BAQsFAAOCAgEAVR9YqbyyqFDQDLHYGmkgJykIrGF1XIpu+ILlaS/V9lZL\nubhzEFnTIZd+50xx+7LSYK05qAvqFyFWhfFQDlnrzuBZ6brJFe+GnY+EgPbk6ZGQ\n3BebYhtF8GaV0nxvwuo77x/Py9auJ/GpsMiu/X1+mvoiBOv/2X/qkSsisRcOj/KK\nNFtY2PwByVS5uCbMiogziUwthDyC3+6WVwW6LLv3xLfHTjuCvjHIInNzktHCgKQ5\nORAzI4JMPJ+GslWYHb4phowim57iaztXOoJwTdwJx4nLCgdNbOhdjsnvzqvHu7Ur\nTkXWStAmzOVyyghqpZXjFaH3pO3JLF+l+/+sKAIuvtd7u+Nxe5AW0wdeRlN8NwdC\njNPElpzVmbUq4JUagEiuTDkHzsxHpFKVK7q4+63SM1N95R1NbdWhscdCb+ZAJzVc\noyi3B43njTOQ5yOf+1CceWxG1bQVs5ZufpsMljq4Ui0/1lvh+wjChP4kqKOJ2qxq\n4RgqsahDYVvTH9w7jXbyLeiNdd8XM2w9U/t7y0Ff/9yi0GE44Za4rF2LN9d11TPA\nmRGunUHBcnWEvgJBQl9nJEiU0Zsnvgc/ubhPgXRR4Xq37Z0j4r7g1SgEEzwxA57d\nemyPxgcYxn/eR44/KJ4EBs+lVDR3veyJm+kXQ99b21/+jh5Xos1AnX5iItreGCc=\n-----END CERTIFICATE-----\n)EOF";\n'; | E1: DEFINITION區 連N拉N | F1: ="Blockly.Arduino.definitions_['"&變數!A2&"'] = "&DEFINITION!F3&F5&F7&";" -> Blockly.Arduino.definitions_['imi_esp32car_init'] = ;
A2: #include <SoftwareSerial.h> | B2: =IF(NOT(ISBLANK(A2)),A2&"\n","") -> #include <SoftwareSerial.h>\n | C2: 【blockly名稱】 | D2: =變數!$A$2 -> imi_esp32car_init
A3: #include <WiFi.h> | B3: =IF(NOT(ISBLANK(A3)),A3&"\n","") -> #include <WiFi.h>\n | C3: 【DEFINITION區程式碼】 | D3: =B2&B3&B4&B5&B6&B7&B8&B9&B10&B11&B12&B13&B14&B15&B16&B17&B18&B19&B20&B21&B22&B23&B24&B25&B26&B27&B28&B29&B30&B31&B32&B33&B34&B35&B36&B37&B38&B39&B40&B41&B42&B43&B44&B45&B46&B47&B48&B49&B50&B51&B52&B53&B54&B55&B56&B57&B58&B59&B60&B61&B62&B63&B64&B65&B66&B67&B68&B69&B70&B71&B72&B73&B74&B75&B76&B77&B78&B79&B80&B81&B82&B83&B84&B85&B86&B87&B88 -> #include <SoftwareSerial.h>\n#include <WiFi.h>\n#include <PubSubClient.h>\n#include <WiFiClientSecure.h>\n//與Mega通訊\nconst char* MAP_SET = "mapSet";\nconst char* GOODS_LOAD = "goodsLoad";\nconst char* LINE_NOTIFY = "lineNotify";\nconst char* CAR_GPS = "carGps";\n//UART通訊\n''SoftwareSerial MegaSerial('+value_rx+',' +value_tx+');'\n//WiFi設定\n''const char* ssid ="' +value_ssid+'";'\n''const char* password ="' +value_wifiPwd+'";'\n//LINE權杖\n''String lineToken ="' +value_lineToken+'";'\n//---- HiveMQ設定 Start -----\nconst char* mqtt_server = "xxxxxxxx.s2.eu.hivemq.cloud";\n''const char* mqtt_username ="' +value_mqttUser+'";'\n''const char* mqtt_password ="' +value_mqttPwd+'";'\n''const int mqtt_port =' +value_mqttPort+';'\n//Topic主題\nconst char* TOPIC_MAP_SET = "imiRobot/map/set";\nconst char* TOPIC_CAR_STANDBY = "imiRobot/car/standby";\nconst char* TOPIC_CAR_GPS = "imiRobot/car/gps";\nconst char* TOPIC_GOODS_LOAD = "imiRobot/goods/load";\nconst char* TOPIC_CAR_LOWPOWER = "imiRobot/car/lowPower";\n//發佈者 傳送的消息內容\nchar* mqttSendMsg = "";\n//訂閱者 接收的消息內容\nString mqttGetMsg = "";\nWiFiClientSecure espClient;\nPubSubClient client(espClient);\n// HiveMQ Cloud Let's Encrypt CA certificate\nstatic const char* root_ca PROGMEM = R"EOF(\n-----BEGIN CERTIFICATE-----\nMIIFazCCA1OgAwIBAgIRAIIQz7DSQONZRGPgu2OCiwAwDQYJKoZIhvcNAQELBQAw\nTzELMAkGA1UEBhMCVVMxKTAnBgNVBAoTIEludGVybmV0IFNlY3VyaXR5IFJlc2Vh\ncmNoIEdyb3VwMRUwEwYDVQQDEwxJU1JHIFJvb3QgWDEwHhcNMTUwNjA0MTEwNDM4\nWhcNMzUwNjA0MTEwNDM4WjBPMQswCQYDVQQGEwJVUzEpMCcGA1UEChMgSW50ZXJu\nZXQgU2VjdXJpdHkgUmVzZWFyY2ggR3JvdXAxFTATBgNVBAMTDElTUkcgUm9vdCBY\nMTCCAiIwDQYJKoZIhvcNAQEBBQADggIPADCCAgoCggIBAK3oJHP0FDfzm54rVygc\nh77ct984kIxuPOZXoHj3dcKi/vVqbvYATyjb3miGbESTtrFj/RQSa78f0uoxmyF+\n0TM8ukj13Xnfs7j/EvEhmkvBioZxaUpmZmyPfjxwv60pIgbz5MDmgK7iS4+3mX6U\nA5/TR5d8mUgjU+g4rk8Kb4Mu0UlXjIB0ttov0DiNewNwIRt18jA8+o+u3dpjq+sW\nT8KOEUt+zwvo/7V3LvSye0rgTBIlDHCNAymg4VMk7BPZ7hm/ELNKjD+Jo2FR3qyH\nB5T0Y3HsLuJvW5iB4YlcNHlsdu87kGJ55tukmi8mxdAQ4Q7e2RCOFvu396j3x+UC\nB5iPNgiV5+I3lg02dZ77DnKxHZu8A/lJBdiB3QW0KtZB6awBdpUKD9jf1b0SHzUv\nKBds0pjBqAlkd25HN7rOrFleaJ1/ctaJxQZBKT5ZPt0m9STJEadao0xAH0ahmbWn\nOlFuhjuefXKnEgV4We0+UXgVCwOPjdAvBbI+e0ocS3MFEvzG6uBQE3xDk3SzynTn\njh8BCNAw1FtxNrQHusEwMFxIt4I7mKZ9YIqioymCzLq9gwQbooMDQaHWBfEbwrbw\nqHyGO0aoSCqI3Haadr8faqU9GY/rOPNk3sgrDQoo//fb4hVC1CLQJ13hef4Y53CI\nrU7m2Ys6xt0nUW7/vGT1M0NPAgMBAAGjQjBAMA4GA1UdDwEB/wQEAwIBBjAPBgNV\nHRMBAf8EBTADAQH/MB0GA1UdDgQWBBR5tFnme7bl5AFzgAiIyBpY9umbbjANBgkq\nhkiG9w0BAQsFAAOCAgEAVR9YqbyyqFDQDLHYGmkgJykIrGF1XIpu+ILlaS/V9lZL\nubhzEFnTIZd+50xx+7LSYK05qAvqFyFWhfFQDlnrzuBZ6brJFe+GnY+EgPbk6ZGQ\n3BebYhtF8GaV0nxvwuo77x/Py9auJ/GpsMiu/X1+mvoiBOv/2X/qkSsisRcOj/KK\nNFtY2PwByVS5uCbMiogziUwthDyC3+6WVwW6LLv3xLfHTjuCvjHIInNzktHCgKQ5\nORAzI4JMPJ+GslWYHb4phowim57iaztXOoJwTdwJx4nLCgdNbOhdjsnvzqvHu7Ur\nTkXWStAmzOVyyghqpZXjFaH3pO3JLF+l+/+sKAIuvtd7u+Nxe5AW0wdeRlN8NwdC\njNPElpzVmbUq4JUagEiuTDkHzsxHpFKVK7q4+63SM1N95R1NbdWhscdCb+ZAJzVc\noyi3B43njTOQ5yOf+1CceWxG1bQVs5ZufpsMljq4Ui0/1lvh+wjChP4kqKOJ2qxq\n4RgqsahDYVvTH9w7jXbyLeiNdd8XM2w9U/t7y0Ff/9yi0GE44Za4rF2LN9d11TPA\nmRGunUHBcnWEvgJBQl9nJEiU0Zsnvgc/ubhPgXRR4Xq37Z0j4r7g1SgEEzwxA57d\nemyPxgcYxn/eR44/KJ4EBs+lVDR3veyJm+kXQ99b21/+jh5Xos1AnX5iItreGCc=\n-----END CERTIFICATE-----\n)EOF";\n
A4: #include <PubSubClient.h> | B4: =IF(NOT(ISBLANK(A4)),A4&"\n","") -> #include <PubSubClient.h>\n
A5: #include <WiFiClientSecure.h> | B5: =IF(NOT(ISBLANK(A5)),A5&"\n","") -> #include <WiFiClientSecure.h>\n
B6: =IF(NOT(ISBLANK(A6)),A6&"\n","")
A7: //與Mega通訊 | B7: =IF(NOT(ISBLANK(A7)),A7&"\n","") -> //與Mega通訊\n
A8: const char* MAP_SET = "mapSet"; | B8: =IF(NOT(ISBLANK(A8)),A8&"\n","") -> const char* MAP_SET = "mapSet";\n
A9: const char* GOODS_LOAD = "goodsLoad"; | B9: =IF(NOT(ISBLANK(A9)),A9&"\n","") -> const char* GOODS_LOAD = "goodsLoad";\n
A10: const char* LINE_NOTIFY = "lineNotify"; | B10: =IF(NOT(ISBLANK(A10)),A10&"\n","") -> const char* LINE_NOTIFY = "lineNotify";\n
A11: const char* CAR_GPS = "carGps"; | B11: =IF(NOT(ISBLANK(A11)),A11&"\n","") -> const char* CAR_GPS = "carGps";\n
B12: =IF(NOT(ISBLANK(A12)),A12&"\n","")
A13: //UART通訊 | B13: =IF(NOT(ISBLANK(A13)),A13&"\n","") -> //UART通訊\n
A14: ''SoftwareSerial MegaSerial('+value_rx+',' +value_tx+');' | B14: =IF(NOT(ISBLANK(A14)),A14&"\n","") -> ''SoftwareSerial MegaSerial('+value_rx+',' +value_tx+');'\n
B15: =IF(NOT(ISBLANK(A15)),A15&"\n","")
A16: //WiFi設定 | B16: =IF(NOT(ISBLANK(A16)),A16&"\n","") -> //WiFi設定\n
A17: ''const char* ssid ="' +value_ssid+'";' | B17: =IF(NOT(ISBLANK(A17)),A17&"\n","") -> ''const char* ssid ="' +value_ssid+'";'\n
B18: =IF(NOT(ISBLANK(A18)),A18&"\n","")
A19: ''const char* password ="' +value_wifiPwd+'";' | B19: =IF(NOT(ISBLANK(A19)),A19&"\n","") -> ''const char* password ="' +value_wifiPwd+'";'\n
B20: =IF(NOT(ISBLANK(A20)),A20&"\n","")
A21: //LINE權杖 | B21: =IF(NOT(ISBLANK(A21)),A21&"\n","") -> //LINE權杖\n
A22: ''String lineToken ="' +value_lineToken+'";' | B22: =IF(NOT(ISBLANK(A22)),A22&"\n","") -> ''String lineToken ="' +value_lineToken+'";'\n
B23: =IF(NOT(ISBLANK(A23)),A23&"\n","")
A24: //---- HiveMQ設定 Start ----- | B24: =IF(NOT(ISBLANK(A24)),A24&"\n","") -> //---- HiveMQ設定 Start -----\n
A25: const char* mqtt_server = "xxxxxxxx.s2.eu.hivemq.cloud"; | B25: =IF(NOT(ISBLANK(A25)),A25&"\n","") -> const char* mqtt_server = "xxxxxxxx.s2.eu.hivemq.cloud";\n
A26: ''const char* mqtt_username ="' +value_mqttUser+'";' | B26: =IF(NOT(ISBLANK(A26)),A26&"\n","") -> ''const char* mqtt_username ="' +value_mqttUser+'";'\n
B27: =IF(NOT(ISBLANK(A27)),A27&"\n","")
A28: ''const char* mqtt_password ="' +value_mqttPwd+'";' | B28: =IF(NOT(ISBLANK(A28)),A28&"\n","") -> ''const char* mqtt_password ="' +value_mqttPwd+'";'\n
B29: =IF(NOT(ISBLANK(A29)),A29&"\n","")
A30: ''const int mqtt_port =' +value_mqttPort+';' | B30: =IF(NOT(ISBLANK(A30)),A30&"\n","") -> ''const int mqtt_port =' +value_mqttPort+';'\n
B31: =IF(NOT(ISBLANK(A31)),A31&"\n","")
B32: =IF(NOT(ISBLANK(A32)),A32&"\n","")
A33: //Topic主題 | B33: =IF(NOT(ISBLANK(A33)),A33&"\n","") -> //Topic主題\n
A34: const char* TOPIC_MAP_SET = "imiRobot/map/set"; | B34: =IF(NOT(ISBLANK(A34)),A34&"\n","") -> const char* TOPIC_MAP_SET = "imiRobot/map/set";\n
A35: const char* TOPIC_CAR_STANDBY = "imiRobot/car/standby"; | B35: =IF(NOT(ISBLANK(A35)),A35&"\n","") -> const char* TOPIC_CAR_STANDBY = "imiRobot/car/standby";\n
A36: const char* TOPIC_CAR_GPS = "imiRobot/car/gps"; | B36: =IF(NOT(ISBLANK(A36)),A36&"\n","") -> const char* TOPIC_CAR_GPS = "imiRobot/car/gps";\n
A37: const char* TOPIC_GOODS_LOAD = "imiRobot/goods/load"; | B37: =IF(NOT(ISBLANK(A37)),A37&"\n","") -> const char* TOPIC_GOODS_LOAD = "imiRobot/goods/load";\n
A38: const char* TOPIC_CAR_LOWPOWER = "imiRobot/car/lowPower"; | B38: =IF(NOT(ISBLANK(A38)),A38&"\n","") -> const char* TOPIC_CAR_LOWPOWER = "imiRobot/car/lowPower";\n
B39: =IF(NOT(ISBLANK(A39)),A39&"\n","")
A40: //發佈者 傳送的消息內容 | B40: =IF(NOT(ISBLANK(A40)),A40&"\n","") -> //發佈者 傳送的消息內容\n
...

Sheet SETUP
A1: SETUP區 1次(程式碼固定不變動) | C1: 完整程式碼： | D1: ="Blockly.Arduino.setups_['"&D2&"'] = '"&D3&"';" -> Blockly.Arduino.setups_['imi_esp32car_init'] = ' delay(500);\n Serial.begin(9600);\n delay(500);\n MegaSerial.begin(9600);\n delay(500);\n setup_wifi();\n //MQTT初始\n espClient.setCACert(root_ca);\n client.setServer(mqtt_server, mqtt_port);\n client.setCallback(callback);\n if (!client.connected()) {\n reconnect();\n }\n'; | E1: SETUP區 連N拉N | F1: ="Blockly.Arduino.setups_['"& 變數!$A$2 &"' + "& 變數!B2 &" + "& 變數!B3 & "] = "& SETUP!F3 & SETUP!F5 &";" -> Blockly.Arduino.setups_['imi_esp32car_init' + value_rx + value_tx] = ++++++++++++++;
A2: delay(500); | B2: =IF(NOT(ISBLANK(A2)),A2&"\n","") -> delay(500);\n | C2: 【blockly名稱】 | D2: =變數!$A$2 -> imi_esp32car_init
A3: Serial.begin(9600); | B3: =IF(NOT(ISBLANK(A3)),A3&"\n","") -> Serial.begin(9600);\n | C3: 【DEFINITION區程式碼】 | D3: =B2&B3&B4&B5&B6&B7&B8&B9&B10&B11&B12&B13&B14&B15&B16&B17&B18&B19&B20&B21&B22&B23&B24&B25&B26&B27&B28&B29&B30&B31&B32&B33&B34&B35&B36&B37&B38&B39&B40&B41&B42&B43&B44&B45&B46&B47&B48&B49&B50&B51&B52&B53&B54&B55&B56&B57&B58&B59&B60&B61&B62&B63&B64&B65&B66&B67&B68&B69&B70&B71&B72&B73&B74&B75&B76&B77&B78&B79&B80&B81&B82&B83&B84&B85&B86&B87&B88 -> delay(500);\n Serial.begin(9600);\n delay(500);\n MegaSerial.begin(9600);\n delay(500);\n setup_wifi();\n //MQTT初始\n espClient.setCACert(root_ca);\n client.setServer(mqtt_server, mqtt_port);\n client.setCallback(callback);\n if (!client.connected()) {\n reconnect();\n }\n | F3: =F2&"+"&G2&"+"&H2&"+"&I2&"+"&J2&"+"&K2&"+"&L2&"+"&M2 -> +++++++
A4: delay(500); | B4: =IF(NOT(ISBLANK(A4)),A4&"\n","") -> delay(500);\n
A5: MegaSerial.begin(9600); | B5: =IF(NOT(ISBLANK(A5)),A5&"\n","") -> MegaSerial.begin(9600);\n | F5: =F4&"+"&G4&"+"&H4&"+"&I4&"+"&J4&"+"&K4&"+"&L4&"+"&M4 -> +++++++
A6: delay(500); | B6: =IF(NOT(ISBLANK(A6)),A6&"\n","") -> delay(500);\n
A7: setup_wifi(); | B7: =IF(NOT(ISBLANK(A7)),A7&"\n","") -> setup_wifi();\n | F7: =F6&"+"&G6&"+"&H6&"+"&I6&"+"&J6&"+"&K6&"+"&L6&"+"&M6 -> +++++++
B8: =IF(NOT(ISBLANK(A8)),A8&"\n","")
A9: //MQTT初始 | B9: =IF(NOT(ISBLANK(A9)),A9&"\n","") -> //MQTT初始\n | F9: =F8&"+"&G8&"+"&H8&"+"&I8&"+"&J8&"+"&K8&"+"&L8&"+"&M8 -> +++++++
A10: espClient.setCACert(root_ca); | B10: =IF(NOT(ISBLANK(A10)),A10&"\n","") -> espClient.setCACert(root_ca);\n
A11: client.setServer(mqtt_server, mqtt_port); | B11: =IF(NOT(ISBLANK(A11)),A11&"\n","") -> client.setServer(mqtt_server, mqtt_port);\n | F11: =F10&"+"&G10&"+"&H10&"+"&I10&"+"&J10&"+"&K10&"+"&L10&"+"&M10 -> +++++++
A12: client.setCallback(callback); | B12: =IF(NOT(ISBLANK(A12)),A12&"\n","") -> client.setCallback(callback);\n
A13: if (!client.connected()) { | B13: =IF(NOT(ISBLANK(A13)),A13&"\n","") -> if (!client.connected()) {\n
A14: reconnect(); | B14: =IF(NOT(ISBLANK(A14)),A14&"\n","") -> reconnect();\n
A15: } | B15: =IF(NOT(ISBLANK(A15)),A15&"\n","") -> }\n
B16: =IF(NOT(ISBLANK(A16)),A16&"\n","")
B17: =IF(NOT(ISBLANK(A17)),A17&"\n","")
B18: =IF(NOT(ISBLANK(A18)),A18&"\n","")
B19: =IF(NOT(ISBLANK(A19)),A19&"\n","")
B20: =IF(NOT(ISBLANK(A20)),A20&"\n","")
B21: =IF(NOT(ISBLANK(A21)),A21&"\n","")
B22: =IF(NOT(ISBLANK(A22)),A22&"\n","")
B23: =IF(NOT(ISBLANK(A23)),A23&"\n","")
B24: =IF(NOT(ISBLANK(A24)),A24&"\n","")
B25: =IF(NOT(ISBLANK(A25)),A25&"\n","")
B26: =IF(NOT(ISBLANK(A26)),A26&"\n","")
B27: =IF(NOT(ISBLANK(A27)),A27&"\n","")
... B88: =IF(NOT(ISBLANK(A88)),A88&"\n","")

Sheet SETUP(1次會變動)
A1: SETUP區 1次(程式碼會變動) | B1: ="Blockly.Arduino.setups_['"&變數!$A$2&"'] = "& 'SETUP(1次會變動)'!B3 & 'SETUP(1次會變動)'!B5 &";" -> Blockly.Arduino.setups_['imi_esp32car_init'] = ''pinMode('+value_swpin+', INPUT_PULLUP);\n '++++++++++++;
A2: ''pinMode('●value_swpin●', INPUT_PULLUP);\n ' | B2: ''pinMode(' | C2: value_swpin | D2: ', INPUT_PULLUP);\n '
B3: =B2&"+"&C2&"+"&D2&"+"&E2&"+"&F2&"+"&G2&"+"&H2&"+"&I2 -> ''pinMode('+value_swpin+', INPUT_PULLUP);\n '+++++
B5: =B4&"+"&C4&"+"&D4&"+"&E4&"+"&F4&"+"&G4&"+"&H4&"+"&I4 -> +++++++
B7: =B6&"+"&C6&"+"&D6&"+"&E6&"+"&F6&"+"&G6&"+"&H6&"+"&I6 -> +++++++
B9: =B8&"+"&C8&"+"&D8&"+"&E8&"+"&F8&"+"&G8&"+"&H8&"+"&I8 -> +++++++
B11: =B10&"+"&C10&"+"&D10&"+"&E10&"+"&F10&"+"&G10&"+"&H10&"+"&I10 -> +++++++

Sheet FUNCTION
A1: FUNCTION區 1次 | C1: 完整程式碼： | D1: ="Blockly.Arduino.functions_['"&D2&"'] = '"&D3&"';" -> Blockly.Arduino.functions_['imi_esp32car_init'] = 'void reconnect() {\n while (!client.connected()) {\n Serial.print("Attempting MQTT connection… ");\n String clientId = "ESP32Client";\n if (client.connect(clientId.c_str(), mqtt_username, mqtt_password)) {\n Serial.println("connected!");\n } else {\n Serial.print("failed, rc = ");\n Serial.print(client.state());\n Serial.println(" try again in 5 seconds");\n delay(5000);\n }\n }\n}\nvoid sendLineMsg(String myMsg) {\n static WiFiClientSecure line_client;\n line_client.setInsecure();\n myMsg.replace("%", "%25");\n myMsg.replace("&", "%26");\n myMsg.replace("§", "&");\n myMsg.replace("\\n", "\n");\n if (line_client.connect("notify-api.line.me", 443)) {\n line_client.println("POST /api/notify HTTP/1.1");\n line_client.println("Connection: close");\n line_client.println("Host: notify-api.line.me");\n line_client.println("Authorization: Bearer " + lineToken);\n line_client.println("Content-Type: application/x-www-form-urlencoded");\n line_client.println("Content-Length: " + String(myMsg.length()));\n line_client.println();\n line_client.println(myMsg);\n line_client.println();\n line_client.stop();\n } else {\n Serial.println("Line Notify failed");\n }\n}\n'; | E1: FUNCTION區 連N拉N
A2: void reconnect() { | B2: =IF(NOT(ISBLANK(A2)),A2&"\n","") -> void reconnect() {\n | C2: 【blockly名稱】 | D2: =變數!$A$2 -> imi_esp32car_init
A3: while (!client.connected()) { | B3: =IF(NOT(ISBLANK(A3)),A3&"\n","") -> while (!client.connected()) {\n | C3: 【DEFINITION區程式碼】 | D3: =B2&B3&B4&B5&B6&B7&B8&B9&B10&B11&B12&B13&B14&B15&B16&B17&B18&B19&B20&B21&B22&B23&B24&B25&B26&B27&B28&B29&B30&B31&B32&B33&B34&B35&B36&B37&B38&B39&B40&B41&B42&B43&B44&B45&B46&B47&B48&B49&B50&B51&B52&B53&B54&B55&B56&B57&B58&B59&B60&B61&B62&B63&B64&B65&B66&B67&B68&B69&B70&B71&B72&B73&B74&B75&B76&B77&B78&B79&B80&B81&B82&B83&B84&B85&B86&B87&B88 -> void reconnect() {\n while (!client.connected()) {\n Serial.print("Attempting MQTT connection… ");\n String clientId = "ESP32Client";\n if (client.connect(clientId.c_str(), mqtt_username, mqtt_password)) {\n Serial.println("connected!");\n } else {\n Serial.print("failed, rc = ");\n Serial.print(client.state());\n Serial.println(" try again in 5 seconds");\n delay(5000);\n }\n }\n}\nvoid sendLineMsg(String myMsg) {\n static WiFiClientSecure line_client;\n line_client.setInsecure();\n myMsg.replace("%", "%25");\n myMsg.replace("&", "%26");\n myMsg.replace("§", "&");\n myMsg.replace("\\n", "\n");\n if (line_client.connect("notify-api.line.me", 443)) {\n line_client.println("POST /api/notify HTTP/1.1");\n line_client.println("Connection: close");\n line_client.println("Host: notify-api.line.me");\n line_client.println("Authorization: Bearer " + lineToken);\n line_client.println("Content-Type: application/x-www-form-urlencoded");\n line_client.println("Content-Length: " + String(myMsg.length()));\n line_client.println();\n line_client.println(myMsg);\n line_client.println();\n line_client.stop();\n } else {\n Serial.println("Line Notify failed");\n }\n}\n
A4: Serial.print("Attempting MQTT connection… "); | B4: =IF(NOT(ISBLANK(A4)),A4&"\n","") -> Serial.print("Attempting MQTT connection… ");\n
A5: String clientId = "ESP32Client"; | B5: =IF(NOT(ISBLANK(A5)),A5&"\n","") -> String clientId = "ESP32Client";\n
A6: if (client.connect(clientId.c_str(), mqtt_username, mqtt_password)) { | B6: =IF(NOT(ISBLANK(A6)),A6&"\n","") -> if (client.connect(clientId.c_str(), mqtt_username, mqtt_password)) {\n
A7: Serial.println("connected!"); | B7: =IF(NOT(ISBLANK(A7)),A7&"\n","") -> Serial.println("connected!");\n
A8: } else { | B8: =IF(NOT(ISBLANK(A8)),A8&"\n","") -> } else {\n
A9: Serial.print("failed, rc = "); | B9: =IF(NOT(ISBLANK(A9)),A9&"\n","") -> Serial.print("failed, rc = ");\n
A10: Serial.print(client.state()); | B10: =IF(NOT(ISBLANK(A10)),A10&"\n","") -> Serial.print(client.state());\n
A11: Serial.println(" try again in 5 seconds"); | B11: =IF(NOT(ISBLANK(A11)),A11&"\n","") -> Serial.println(" try again in 5 seconds");\n
A12: delay(5000); | B12: =IF(NOT(ISBLANK(A12)),A12&"\n","") -> delay(5000);\n
A13: } | B13: =IF(NOT(ISBLANK(A13)),A13&"\n","") -> }\n
A14: } | B14: =IF(NOT(ISBLANK(A14)),A14&"\n","") -> }\n
A15: } | B15: =IF(NOT(ISBLANK(A15)),A15&"\n","") -> }\n
B16: =IF(NOT(ISBLANK(A16)),A16&"\n","")
A17: void sendLineMsg(String myMsg) { | B17: =IF(NOT(ISBLANK(A17)),A17&"\n","") -> void sendLineMsg(String myMsg) {\n
A18: static WiFiClientSecure line_client; | B18: =IF(NOT(ISBLANK(A18)),A18&"\n","") -> static WiFiClientSecure line_client;\n
A19: line_client.setInsecure(); | B19: =IF(NOT(ISBLANK(A19)),A19&"\n","") -> line_client.setInsecure();\n
A20: myMsg.replace("%", "%25"); | B20: =IF(NOT(ISBLANK(A20)),A20&"\n","") -> myMsg.replace("%", "%25");\n
A21: myMsg.replace("&", "%26"); | B21: =IF(NOT(ISBLANK(A21)),A21&"\n","") -> myMsg.replace("&", "%26");\n
A22: myMsg.replace("§", "&"); | B22: =IF(NOT(ISBLANK(A22)),A22&"\n","") -> myMsg.replace("§", "&");\n
A23: myMsg.replace("\\n", "\n"); | B23: =IF(NOT(ISBLANK(A23)),A23&"\n","") -> myMsg.replace("\\n", "\n");\n
A24: if (line_client.connect("notify-api.line.me", 443)) { | B24: =IF(NOT(ISBLANK(A24)),A24&"\n","") -> if (line_client.connect("notify-api.line.me", 443)) {\n
A25: line_client.println("POST /api/notify HTTP/1.1"); | B25: =IF(NOT(ISBLANK(A25)),A25&"\n","") -> line_client.println("POST /api/notify HTTP/1.1");\n
A26: line_client.println("Connection: close"); | B26: =IF(NOT(ISBLANK(A26)),A26&"\n","") -> line_client.println("Connection: close");\n
A27: line_client.println("Host: notify-api.line.me"); | B27: =IF(NOT(ISBLANK(A27)),A27&"\n","") -> line_client.println("Host: notify-api.line.me");\n
A28: line_client.println("Authorization: Bearer " + lineToken); | B28: =IF(NOT(ISBLANK(A28)),A28&"\n","") -> line_client.println("Authorization: Bearer " + lineToken);\n
... A38: } | B38: =IF(NOT(ISBLANK(A38)),A38&"\n","") -> }\n
B39: =IF(NOT(ISBLANK(A39)),A39&"\n","")
B40: =IF(NOT(ISBLANK(A40)),A40&"\n","")
B41: =IF(NOT(ISBLANK(A41)),A41&"\n","")
B42: =IF(NOT(ISBLANK(A42)),A42&"\n","")
B43: =IF(NOT(ISBLANK(A43)),A43&"\n","")
B44: =IF(NOT(ISBLANK(A44)),A44&"\n","")
B45: =IF(NOT(ISBLANK(A45)),A45&"\n","")
B46: =IF(NOT(ISBLANK(A46)),A46&"\n","")
B47: =IF(NOT(ISBLANK(A47)),A47&"\n","")
B48: =IF(NOT(ISBLANK(A48)),A48&"\n","")
B49: =IF(NOT(ISBLANK(A49)),A49&"\n","")
...

Sheet LOOP_init
A1: LOOP區 1次 | C1: LOOP區 連N拉N | D1: ="var code ="&D3&D5&";" -> var code =''tm_display'+value_clk+ value_dio+'.showNumberDecEx('+value_num1+', 0x40, true, 2, 0); \n'++''tm_display'+value_clk +value_dio+'.showNumberDecEx('+value_num2+', 0, false, 2, 2); \n '++;
C2: ''tm_display'●value_clk● value_dio●'.showNumberDecEx('●value_num1●', 0x40, true, 2, 0); \n' | D2: ''tm_display' | E2: value_clk | F2: value_dio | G2: '.showNumberDecEx(' | H2: value_num1 | I2: ', 0x40, true, 2, 0); \n'
D3: =D2&"+"&E2&"+"&F2&"+"&G2&"+"&H2&"+"&I2&"+"&J2&"+"&K2 -> ''tm_display'+value_clk+ value_dio+'.showNumberDecEx('+value_num1+', 0x40, true, 2, 0); \n'++
C4: ''tm_display'●value_clk ●value_dio●'.showNumberDecEx('●value_num2●', 0, false, 2, 2); \n ' | D4: ''tm_display' | E4: value_clk | F4: value_dio | G4: '.showNumberDecEx(' | H4: value_num2 | I4: ', 0, false, 2, 2); \n '
D5: =D4&"+"&E4&"+"&F4&"+"&G4&"+"&H4&"+"&I4&"+"&J4&"+"&K4 -> ''tm_display'+value_clk +value_dio+'.showNumberDecEx('+value_num2+', 0, false, 2, 2); \n '++
D7: =D6&"+"&E6&"+"&F6&"+"&G6&"+"&H6&"+"&I6&"+"&J6&"+"&K6 -> +++++++
D9: =D8&"+"&E8&"+"&F8&"+"&G8&"+"&H8&"+"&I8&"+"&J8&"+"&K8 -> +++++++
D11: =D10&"+"&E10&"+"&F10&"+"&G10&"+"&H10&"+"&I10&"+"&J10&"+"&K10 -> +++++++
